==============================================================================
20230425 15:55:53.815 - INFO - + START SUITE: TEST DEMO [ ]
==============================================================================
20230425 15:55:53.816 - INFO - +- START SETUP: GX1Testlib.Init Test [ ]
20230425 15:55:53.817 - INFO - Loading the project at D:\Workspace\GX1\G1XAutomation\Demo_Auto_Test
20230425 15:55:53.841 - INFO - Squish Hook 192.168.80.130, gx1, C:\Users\xuf\.ssh\bsci
20230425 15:55:53.841 - INFO - Demo_Auto_Test has been loaded successfully
20230425 15:55:53.848 - INFO - connecting to device
20230425 15:55:53.852 - INFO - COM Port COM4 created successfully
20230425 15:55:53.962 - INFO - GX1 Simulator is started
20230425 15:55:55.995 - FAIL - NamingError: Failed to locate the nameserver
20230425 15:55:56.038 - DEBUG - Traceback (most recent call last):
  File "D:\Workspace\GX1\G1XAutomation\venv\lib\site-packages\Pyro5\client.py", line 310, in connect_and_handshake
    sock = socketutil.create_socket(connect=connect_location,
  File "D:\Workspace\GX1\G1XAutomation\venv\lib\site-packages\Pyro5\socketutil.py", line 283, in create_socket
    sock.connect(connect)
ConnectionRefusedError: [WinError 10061] 由于目标计算机积极拒绝，无法连接。

The above exception was the direct cause of the following exception:

Traceback (most recent call last):
  File "D:\Workspace\GX1\G1XAutomation\venv\lib\site-packages\Pyro5\core.py", line 281, in locate_ns
    proxy._pyroBind()
  File "D:\Workspace\GX1\G1XAutomation\venv\lib\site-packages\Pyro5\client.py", line 214, in _pyroBind
    return self.__pyroCreateConnection(True)
  File "D:\Workspace\GX1\G1XAutomation\venv\lib\site-packages\Pyro5\client.py", line 376, in __pyroCreateConnection
    connect_and_handshake(conn)
  File "D:\Workspace\GX1\G1XAutomation\venv\lib\site-packages\Pyro5\client.py", line 336, in connect_and_handshake
    raise errors.CommunicationError(err) from x
Pyro5.errors.CommunicationError: cannot connect to ('127.0.0.1', 9090): [WinError 10061] 由于目标计算机积极拒绝，无法连接。

The above exception was the direct cause of the following exception:

Traceback (most recent call last):
  File "D:\Workspace\GX1\G1XAutomation\GX1Testlib.py", line 291, in init_test
    self.squish_proxy.create_proxy()
  File "D:\Workspace\GX1\G1XAutomation\squish\squish_proxy.py", line 22, in create_proxy
    with locate_ns(host='127.0.0.1') as ns:
  File "D:\Workspace\GX1\G1XAutomation\venv\lib\site-packages\Pyro5\core.py", line 285, in locate_ns
    raise errors.NamingError("Failed to locate the nameserver") from x
Pyro5.errors.NamingError: Failed to locate the nameserver
20230425 15:55:56.039 - INFO - +- END SETUP: GX1Testlib.Init Test (2222)
------------------------------------------------------------------------------
20230425 15:55:56.039 - INFO - +- START TEST: TEST_CASE_1_COMMAND_SIMULATION [ ]
------------------------------------------------------------------------------
20230425 15:55:56.040 - INFO - +- END TEST: TEST_CASE_1_COMMAND_SIMULATION (1)
------------------------------------------------------------------------------
20230425 15:55:56.041 - INFO - +- START TEST: TEST_CASE_2_CLICK_AND_SCREEN_SHOT [ ]
------------------------------------------------------------------------------
20230425 15:55:56.042 - INFO - +- END TEST: TEST_CASE_2_CLICK_AND_SCREEN_SHOT (0)
------------------------------------------------------------------------------
20230425 15:55:56.042 - INFO - +- START TEST: TEST_CASE_3_COMMAND_SEARCH [ ]
------------------------------------------------------------------------------
20230425 15:55:56.043 - INFO - +- END TEST: TEST_CASE_3_COMMAND_SEARCH (1)
------------------------------------------------------------------------------
20230425 15:55:56.043 - INFO - +- START TEST: TEST_CASE_4_TEST_OCR [ ]
------------------------------------------------------------------------------
20230425 15:55:56.044 - INFO - +- END TEST: TEST_CASE_4_TEST_OCR (1)
------------------------------------------------------------------------------
20230425 15:55:56.045 - INFO - +- START TEST: TEST_CASE_5_TEST_COMPARE [ ]
------------------------------------------------------------------------------
20230425 15:55:56.046 - INFO - +- END TEST: TEST_CASE_5_TEST_COMPARE (0)
------------------------------------------------------------------------------
20230425 15:55:56.046 - INFO - +- START TEARDOWN: GX1Testlib.Close Test [ ]
20230425 15:55:57.050 - INFO - disconnecting from device
20230425 15:55:57.050 - INFO - GX1 Simulator is stopped
20230425 15:55:57.050 - FAIL - AttributeError: 'NoneType' object has no attribute 'disconnect'
20230425 15:55:57.050 - DEBUG - Traceback (most recent call last):
  File "D:\Workspace\GX1\G1XAutomation\GX1Testlib.py", line 320, in close_test
    self.squish_proxy.disconnect()
  File "D:\Workspace\GX1\G1XAutomation\squish\squish_proxy.py", line 33, in disconnect
    return self.proxy.disconnect()
AttributeError: 'NoneType' object has no attribute 'disconnect'
20230425 15:55:57.050 - INFO - +- END TEARDOWN: GX1Testlib.Close Test (1004)
==============================================================================
20230425 15:55:57.051 - INFO - + END SUITE: TEST DEMO (3462)
==============================================================================
